Workbook

Sheet Übersicht
A1: Adventskalender 2026 – Übersicht
A2: Heute: | B2: =TODAY() -> 46319
A3: Verkauf live (29.10.) in Tagen: | B3: =DATE(2026,10,29)-TODAY() -> 5
A4: Early Bird endet (15.11.) in Tagen: | B4: =DATE(2026,11,15)-TODAY() -> 22
A5: Kalender startet (1.12.) in Tagen: | B5: =DATE(2026,12,1)-TODAY() -> 38
A6: Aufgaben gesamt / erledigt / offen: | B6: =COUNTA(Gesamtplan!C2:C157) -> 156 | C6: =COUNTIF(Gesamtplan!H2:H157,"erledigt") -> 14 | D6: =B6-C6 -> 142
A7: Überfällig: | B7: =COUNTIF(Gesamtplan!M2:M157,"ÜBERFÄLLIG") -> 0
A8: Bald fällig (2 Tage): | B8: =COUNTIF(Gesamtplan!M2:M157,"bald fällig") -> 11
A10: Bereich | B10: Aufgaben | C10: erledigt | D10: offen | E10: überfällig
A11: Orga & Budget | B11: =COUNTIF(Gesamtplan!$B$2:$B$157,A11) -> 11 | C11: =COUNTIFS(Gesamtplan!$B$2:$B$157,A11,Gesamtplan!$H$2:$H$157,"erledigt") -> 3 | D11: =B11-C11 -> 8 | E11: =COUNTIFS(Gesamtplan!$B$2:$B$157,A11,Gesamtplan!$M$2:$M$157,"ÜBERFÄLLIG") -> 0
A12: Produktion | B12: =COUNTIF(Gesamtplan!$B$2:$B$157,A12) -> 25 | C12: =COUNTIFS(Gesamtplan!$B$2:$B$157,A12,Gesamtplan!$H$2:$H$157,"erledigt") -> 2 | D12: =B12-C12 -> 23 | E12: =COUNTIFS(Gesamtplan!$B$2:$B$157,A12,Gesamtplan!$M$2:$M$157,"ÜBERFÄLLIG") -> 0
A13: Shop & Technik | B13: =COUNTIF(Gesamtplan!$B$2:$B$157,A13) -> 18 | C13: =COUNTIFS(Gesamtplan!$B$2:$B$157,A13,Gesamtplan!$H$2:$H$157,"erledigt") -> 0 | D13: =B13-C13 -> 18 | E13: =COUNTIFS(Gesamtplan!$B$2:$B$157,A13,Gesamtplan!$M$2:$M$157,"ÜBERFÄLLIG") -> 0
A14: Warteliste & Mail | B14: =COUNTIF(Gesamtplan!$B$2:$B$157,A14) -> 20 | C14: =COUNTIFS(Gesamtplan!$B$2:$B$157,A14,Gesamtplan!$H$2:$H$157,"erledigt") -> 4 | D14: =B14-C14 -> 16 | E14: =COUNTIFS(Gesamtplan!$B$2:$B$157,A14,Gesamtplan!$M$2:$M$157,"ÜBERFÄLLIG") -> 0
A15: Werbung organisch | B15: =COUNTIF(Gesamtplan!$B$2:$B$157,A15) -> 22 | C15: =COUNTIFS(Gesamtplan!$B$2:$B$157,A15,Gesamtplan!$H$2:$H$157,"erledigt") -> 0 | D15: =B15-C15 -> 22 | E15: =COUNTIFS(Gesamtplan!$B$2:$B$157,A15,Gesamtplan!$M$2:$M$157,"ÜBERFÄLLIG") -> 0
A16: Werbung bezahlt | B16: =COUNTIF(Gesamtplan!$B$2:$B$157,A16) -> 13 | C16: =COUNTIFS(Gesamtplan!$B$2:$B$157,A16,Gesamtplan!$H$2:$H$157,"erledigt") -> 0 | D16: =B16-C16 -> 13 | E16: =COUNTIFS(Gesamtplan!$B$2:$B$157,A16,Gesamtplan!$M$2:$M$157,"ÜBERFÄLLIG") -> 0
A17: Gewinnspiel | B17: =COUNTIF(Gesamtplan!$B$2:$B$157,A17) -> 19 | C17: =COUNTIFS(Gesamtplan!$B$2:$B$157,A17,Gesamtplan!$H$2:$H$157,"erledigt") -> 3 | D17: =B17-C17 -> 16 | E17: =COUNTIFS(Gesamtplan!$B$2:$B$157,A17,Gesamtplan!$M$2:$M$157,"ÜBERFÄLLIG") -> 0
A18: Recht & Rechte | B18: =COUNTIF(Gesamtplan!$B$2:$B$157,A18) -> 9 | C18: =COUNTIFS(Gesamtplan!$B$2:$B$157,A18,Gesamtplan!$H$2:$H$157,"erledigt") -> 1 | D18: =B18-C18 -> 8 | E18: =COUNTIFS(Gesamtplan!$B$2:$B$157,A18,Gesamtplan!$M$2:$M$157,"ÜBERFÄLLIG") -> 0
A19: Korea & USA | B19: =COUNTIF(Gesamtplan!$B$2:$B$157,A19) -> 12 | C19: =COUNTIFS(Gesamtplan!$B$2:$B$157,A19,Gesamtplan!$H$2:$H$157,"erledigt") -> 1 | D19: =B19-C19 -> 11 | E19: =COUNTIFS(Gesamtplan!$B$2:$B$157,A19,Gesamtplan!$M$2:$M$157,"ÜBERFÄLLIG") -> 0
A20: Betrieb Dezember | B20: =COUNTIF(Gesamtplan!$B$2:$B$157,A20) -> 7 | C20: =COUNTIFS(Gesamtplan!$B$2:$B$157,A20,Gesamtplan!$H$2:$H$157,"erledigt") -> 0 | D20: =B20-C20 -> 7 | E20: =COUNTIFS(Gesamtplan!$B$2:$B$157,A20,Gesamtplan!$M$2:$M$157,"ÜBERFÄLLIG") -> 0
A21: Summe | B21: =SUM(B11:B20) -> 156 | C21: =SUM(C11:C20) -> 14 | D21: =SUM(D11:D20) -> 142 | E21: =SUM(E11:E20) -> 0
A23: So benutzt du die Tabelle
A24: Blatt „Gesamtplan“: alle Aufgaben nach Frist sortiert. Spalte Status per Auswahlliste ändern (offen, in Arbeit, erledigt, wartet, verschoben).
A25: Gelb markiert in der Spalte Herkunft = Vorschlag von Claude (❓), noch nicht entschieden. Ändere Datum, Wer oder Inhalt einfach direkt.
A26: Spalte Warnung zeigt ÜBERFÄLLIG (rot) und bald fällig (orange) automatisch anhand des heutigen Datums.
A27: Blatt „Termine“: die harten Fristen. Blatt „Werbung“: die Werbephasen. Blatt „Offene Fragen“: was Claude von dir braucht.
A28: Quelle: Beschlüsse von Jannik (24.10.2026) und Vault-Notizen. Alles mit Herkunft „Vorschlag ❓“ ist eine Annahme von Claude.
A29: Beispiel einer eigenen Zeile: Nr 999 | Werbung organisch | Reel mit Hinweis posten | 05.11.2026 | 06.11.2026 | Jannik | offen | mittel | Teaser | Vorschlag ❓ | Notiz

Sheet Gesamtplan
A1: Nr | B1: Bereich | C1: Aufgabe | D1: Start | E1: Frist | F1: Tag | G1: Wer | H1: Status | I1: Priorität | J1: Braucht / Abhängigkeit | K1: Herkunft | L1: Notiz | M1: Warnung
A2: 1 | B2: Warteliste & Mail | C2: Warteliste auf der Website erstellt und freigeschaltet | D2: 46319 | E2: 46319 | F2: =CHOOSE(WEEKDAY(E2,2),"Mo","Di","Mi","Do","Fr","Sa","So") -> Sa | G2: Jannik | H2: erledigt | I2: mittel | K2: Beschluss Jannik | M2: =IF(H2="erledigt","",IF(E2<TODAY(),"ÜBERFÄLLIG",IF(E2-TODAY()<=2,"bald fällig","")))
A3: 2 | B3: Warteliste & Mail | C3: Brevo-Warteliste erstellt, Double-Opt-In aktiv | D3: 46319 | E3: 46319 | F3: =CHOOSE(WEEKDAY(E3,2),"Mo","Di","Mi","Do","Fr","Sa","So") -> Sa | G3: Jannik | H3: erledigt | I3: mittel | K3: Beschluss Jannik | M3: =IF(H3="erledigt","",IF(E3<TODAY(),"ÜBERFÄLLIG",IF(E3-TODAY()<=2,"bald fällig","")))
A4: 3 | B4: Produktion | C4: 3 Videos gedreht: I will follow him, Herbei oh ihr Gläubigen, Fill my cup Lord | D4: 46319 | E4: 46319 | F4: =CHOOSE(WEEKDAY(E4,2),"Mo","Di","Mi","Do","Fr","Sa","So") -> Sa | G4: Jannik/David | H4: erledigt | I4: mittel | K4: Beschluss Jannik | M4: =IF(H4="erledigt","",IF(E4<TODAY(),"ÜBERFÄLLIG",IF(E4-TODAY()<=2,"bald fällig","")))
A5: 4 | B5: Gewinnspiel | C5: YouTube-Kommentar-Auswahl-Tool ausgesucht | D5: 46319 | E5: 46319 | F5: =CHOOSE(WEEKDAY(E5,2),"Mo","Di","Mi","Do","Fr","Sa","So") -> Sa | G5: Jannik | H5: erledigt | I5: mittel | K5: Beschluss Jannik | M5: =IF(H5="erledigt","",IF(E5<TODAY(),"ÜBERFÄLLIG",IF(E5-TODAY()<=2,"bald fällig","")))
A6: 5 | B6: Recht & Rechte | C6: Gewerbemeldebestätigung für TikTok besorgt | D6: 46319 | E6: 46319 | F6: =CHOOSE(WEEKDAY(E6,2),"Mo","Di","Mi","Do","Fr","Sa","So") -> Sa | G6: Jannik | H6: erledigt | I6: mittel | K6: Beschluss Jannik | M6: =IF(H6="erledigt","",IF(E6<TODAY(),"ÜBERFÄLLIG",IF(E6-TODAY()<=2,"bald fällig","")))
A7: 6 | B7: Warteliste & Mail | C7: Altliste geprüft: Newsletter mit Konzerten 2027 + Warteliste-Hinweis erlaubt | D7: 46319 | E7: 46319 | F7: =CHOOSE(WEEKDAY(E7,2),"Mo","Di","Mi","Do","Fr","Sa","So") -> Sa | G7: Jannik | H7: erledigt | I7: mittel | K7: Beschluss Jannik | M7: =IF(H7="erledigt","",IF(E7<TODAY(),"ÜBERFÄLLIG",IF(E7-TODAY()<=2,"bald fällig","")))
A8: 7 | B8: Orga & Budget | C8: Konzept, Preise (25 € / 29,99 €), Ablauf, Lose-Modell (1 / 2 Lose), Termine festgelegt | D8: 46319 | E8: 46319 | F8: =CHOOSE(WEEKDAY(E8,2),"Mo","Di","Mi","Do","Fr","Sa","So") -> Sa | G8: Jannik | H8: erledigt | I8: mittel | K8: Beschluss Jannik | M8: =IF(H8="erledigt","",IF(E8<TODAY(),"ÜBERFÄLLIG",IF(E8-TODAY()<=2,"bald fällig","")))
A9: 8 | B9: Orga & Budget | C9: Vault aufgebaut: Planung, Songtabelle, Drehplan, Texte, Impressum, Rechts-Briefing | D9: 46319 | E9: 46319 | F9: =CHOOSE(WEEKDAY(E9,2),"Mo","Di","Mi","Do","Fr","Sa","So") -> Sa | G9: Claude | H9: erledigt | I9: mittel | K9: Claude erledigt | M9: =IF(H9="erledigt","",IF(E9<TODAY(),"ÜBERFÄLLIG",IF(E9-TODAY()<=2,"bald fällig","")))
A10: 9 | B10: Gewinnspiel | C10: Teilnahmebedingungen und Ziehungs-Skript (Entwurf) erstellt | D10: 46319 | E10: 46319 | F10: =CHOOSE(WEEKDAY(E10,2),"Mo","Di","Mi","Do","Fr","Sa","So") -> Sa | G10: Claude | H10: erledigt | I10: mittel | K10: Claude erledigt | M10: =IF(H10="erledigt","",IF(E10<TODAY(),"ÜBERFÄLLIG",IF(E10-TODAY()<=2,"bald fällig","")))
A11: 10 | B11: Warteliste & Mail | C11: Landingpage-Text und 7 Brevo-Mails (Deutsch, Entwurf) geschrieben | D11: 46319 | E11: 46319 | F11: =CHOOSE(WEEKDAY(E11,2),"Mo","Di","Mi","Do","Fr","Sa","So") -> Sa | G11: Claude | H11: erledigt | I11: mittel | K11: Claude erledigt | M11: =IF(H11="erledigt","",IF(E11<TODAY(),"ÜBERFÄLLIG",IF(E11-TODAY()<=2,"bald fällig","")))
A12: 11 | B12: Produktion | C12: Liedliste (alle Lieder, auch die neuen) in den Chat schicken | D12: 46319 | E12: 46320 | F12: =CHOOSE(WEEKDAY(E12,2),"Mo","Di","Mi","Do","Fr","Sa","So") -> So | G12: Jannik | H12: offen | I12: hoch | K12: Blocker | M12: =IF(H12="erledigt","",IF(E12<TODAY(),"ÜBERFÄLLIG",IF(E12-TODAY()<=2,"bald fällig",""))) -> bald fällig
A13: 12 | B13: Warteliste & Mail | C13: Konzertseiten-Text (Konzerte 2027) in den Chat kopieren | D13: 46319 | E13: 46320 | F13: =CHOOSE(WEEKDAY(E13,2),"Mo","Di","Mi","Do","Fr","Sa","So") -> So | G13: Jannik | H13: offen | I13: hoch | K13: Blocker | L13: Claude kann die Homepage nicht öffnen. | M13: =IF(H13="erledigt","",IF(E13<TODAY(),"ÜBERFÄLLIG",IF(E13-TODAY()<=2,"bald fällig",""))) -> bald fällig
A14: 13 | B14: Warteliste & Mail | C14: Landingpage-Link oder -Text der aktuellen Warteliste schicken | D14: 46319 | E14: 46320 | F14: =CHOOSE(WEEKDAY(E14,2),"Mo","Di","Mi","Do","Fr","Sa","So") -> So | G14: Jannik | H14: offen | I14: hoch | K14: Blocker | M14: =IF(H14="erledigt","",IF(E14<TODAY(),"ÜBERFÄLLIG",IF(E14-TODAY()<=2,"bald fällig",""))) -> bald fällig
A15: 14 | B15: Warteliste & Mail | C15: Homepage-Konzertseite: Zugriff für Claude klären (kein Browser in dieser Sitzung); Text kopieren | D15: 46320 | E15: 46320 | F15: =CHOOSE(WEEKDAY(E15,2),"Mo","Di","Mi","Do","Fr","Sa","So") -> So | G15: Jannik | H15: offen | I15: hoch | K15: Blocker | L15: Claude hat in dieser Sitzung keinen Browser-Zugang. | M15: =IF(H15="erledigt","",IF(E15<TODAY(),"ÜBERFÄLLIG",IF(E15-TODAY()<=2,"bald fällig",""))) -> bald fällig
A16: 15 | B16: Orga & Budget | C16: Team festlegen: wer macht was, wie viele Stunden pro Woche | D16: 46319 | E16: 46321 | F16: =CHOOSE(WEEKDAY(E16,2),"Mo","Di","Mi","Do","Fr","Sa","So") -> Mo | G16: Jannik + Eltern | H16: erledigt | I16: hoch | K16: Beschluss Jannik | L16: Ohne Zuständigkeiten stockt alles. Jannik 20 Std./Woche (Social Media, Warteliste, Website/Shop, Konzerte, Videoschnitt). Mutter: Videodreh. Vater: vor der Kamera. Eltern zusammen ca. 10 Std./Woche. | M16: =IF(H16="erledigt","",IF(E16<TODAY(),"ÜBERFÄLLIG",IF(E16-TODAY()<=2,"bald fällig","")))
A17: 16 | B17: Produktion | C17: Dreh-Termine mit David festlegen (Studio Paraguay, ganze Blöcke) | D17: 46319 | E17: 46321 | F17: =CHOOSE(WEEKDAY(E17,2),"Mo","Di","Mi","Do","Fr","Sa","So") -> Mo | G17: Jannik + David | H17: offen | I17: hoch | K17: Blocker | L17: 21 Videos offen, bis 15.11. | M17: =IF(H17="erledigt","",IF(E17<TODAY(),"ÜBERFÄLLIG",IF(E17-TODAY()<=2,"bald fällig",""))) -> bald fällig
A18: 17 | B18: Shop & Technik | C18: Zugangssystem entscheiden: Plugin im Shop oder eigener Server? Wer baut es? | D18: 46319 | E18: 46321 | F18: =CHOOSE(WEEKDAY(E18,2),"Mo","Di","Mi","Do","Fr","Sa","So") -> Mo | G18: Jannik | H18: offen | I18: hoch | J18: Admin-Zugang, Pluginliste | K18: Blocker | L18: Größtes Risiko für Do 29.10. | M18: =IF(H18="erledigt","",IF(E18<TODAY(),"ÜBERFÄLLIG",IF(E18-TODAY()<=2,"bald fällig",""))) -> bald fällig
A19: 18 | B19: Shop & Technik | C19: Admin-Zugang und Umsetzer klären (WordPress/WooCommerce) | D19: 46319 | E19: 46321 | F19: =CHOOSE(WEEKDAY(E19,2),"Mo","Di","Mi","Do","Fr","Sa","So") -> Mo | G19: Jannik | H19: offen | I19: hoch | K19: Beschluss Jannik | M19: =IF(H19="erledigt","",IF(E19<TODAY(),"ÜBERFÄLLIG",IF(E19-TODAY()<=2,"bald fällig",""))) -> bald fällig
A20: 19 | B20: Warteliste & Mail | C20: Absender in Brevo festlegen (Name und Adresse) | D20: 46319 | E20: 46321 | F20: =CHOOSE(WEEKDAY(E20,2),"Mo","Di","Mi","Do","Fr","Sa","So") -> Mo | G20: Jannik | H20: offen | I20: hoch | K20: Beschluss Jannik | L20: Jannik nennt ihn später. | M20: =IF(H20="erledigt","",IF(E20<TODAY(),"ÜBERFÄLLIG",IF(E20-TODAY()<=2,"bald fällig",""))) -> bald fällig
A21: 20 | B21: Recht & Rechte | C21: GEMA und Labels anfragen (Songtabelle, Mail-Entwurf im Vault) | D21: 46319 | E21: 46321 | F21: =CHOOSE(WEEKDAY(E21,2),"Mo","Di","Mi","Do","Fr","Sa","So") -> Mo | G21: Jannik | H21: offen | I21: hoch | J21: Liedliste final | K21: Beschluss Jannik | L21: Antworten dauern Wochen, deshalb sofort. | M21: =IF(H21="erledigt","",IF(E21<TODAY(),"ÜBERFÄLLIG",IF(E21-TODAY()<=2,"bald fällig",""))) -> bald fällig
A22: 21 | B22: Recht & Rechte | C22: GEMA: Lizenz für Bezahlseite auf eigener Webseite klären | D22: 46319 | E22: 46321 | F22: =CHOOSE(WEEKDAY(E22,2),"Mo","Di","Mi","Do","Fr","Sa","So") -> Mo | G22: Jannik | H22: offen | I22: hoch | K22: Vorschlag ❓ (Claude) | M22: =IF(H22="erledigt","",IF(E22<TODAY(),"ÜBERFÄLLIG",IF(E22-TODAY()<=2,"bald fällig",""))) -> bald fällig
A23: 22 | B23: Korea & USA | C23: Mama erinnern: koreanische Community und Mr. Lee ansprechen | D23: 46321 | E23: 46321 | F23: =CHOOSE(WEEKDAY(E23,2),"Mo","Di","Mi","Do","Fr","Sa","So") -> Mo | G23: Jannik | H23: offen | I23: hoch | K23: Beschluss Jannik | L23: Kalendereintrag Mo 26.10. angelegt. | M23: =IF(H23="erledigt","",IF(E23<TODAY(),"ÜBERFÄLLIG",IF(E23-TODAY()<=2,"bald fällig",""))) -> bald fällig
A24: 23 | B24: Produktion | C24: Videoformat entscheiden (16:9 für den Kalender, Kurzvideos hochkant) | D24: 46320 | E24: 46321 | F24: =CHOOSE(WEEKDAY(E24,2),"Mo","Di","Mi","Do","Fr","Sa","So") -> Mo | G24: Jannik | H24: erledigt | I24: mittel | K24: Beschluss Jannik | L24: 16:9 für den Kalender. | M24: =IF(H24="erledigt","",IF(E24<TODAY(),"ÜBERFÄLLIG",IF(E24-TODAY()<=2,"bald fällig","")))
A25: 24 | B25: Orga & Budget | C25: Gesamtbudget festlegen (Tools, Werbung, Preise, Rechtsprüfung, Porto) | D25: 46319 | E25: 46322 | F25: =CHOOSE(WEEKDAY(E25,2),"Mo","Di","Mi","Do","Fr","Sa","So") -> Di | G25: Jannik + Eltern | H25: offen | I25: hoch | K25: Blocker | L25: Jannik wollte nachfragen. | M25: =IF(H25="erledigt","",IF(E25<TODAY(),"ÜBERFÄLLIG",IF(E25-TODAY()<=2,"bald fällig","")))
A26: 25 | B26: Produktion | C26: Songs final festlegen: 10 Lied-Videos + 4 Musikvideos, Playback eigen oder fremd | D26: 46320 | E26: 46322 | F26: =CHOOSE(WEEKDAY(E26,2),"Mo","Di","Mi","Do","Fr","Sa","So") -> Di | G26: Jannik + David | H26: offen | I26: hoch | J26: Liedliste | K26: Blocker | M26: =IF(H26="erledigt","",IF(E26<TODAY(),"ÜBERFÄLLIG",IF(E26-TODAY()<=2,"bald fällig","")))
A27: 26 | B27: Shop & Technik | C27: Produkt „Adventskalender 2026“ im Shop anlegen (25 €, ab 16.11. 29,99 €) | D27: 46322 | E27: 46322 | F27: =CHOOSE(WEEKDAY(E27,2),"Mo","Di","Mi","Do","Fr","Sa","So") -> Di | G27: Jannik | H27: offen | I27: hoch | J27: Zugangssystem | K27: Beschluss Jannik | L27: Aktionspreis zeitlich planen (❓ prüfen). | M27: =IF(H27="erledigt","",IF(E27<TODAY(),"ÜBERFÄLLIG",IF(E27-TODAY()<=2,"bald fällig","")))
A28: 27 | B28: Shop & Technik | C28: PayPal im Shop prüfen, weitere Zahlarten klären | D28: 46322 | E28: 46322 | F28: =CHOOSE(WEEKDAY(E28,2),"Mo","Di","Mi","Do","Fr","Sa","So") -> Di | G28: Jannik | H28: offen | I28: hoch | K28: Beschluss Jannik | M28: =IF(H28="erledigt","",IF(E28<TODAY(),"ÜBERFÄLLIG",IF(E28-TODAY()<=2,"bald fällig","")))
A29: 28 | B29: Werbung organisch | C29: Werbeplan (Kanäle, Rhythmus, Botschaften) final abstimmen | D29: 46320 | E29: 46322 | F29: =CHOOSE(WEEKDAY(E29,2),"Mo","Di","Mi","Do","Fr","Sa","So") -> Di | G29: Jannik + Claude | H29: offen | I29: hoch | J29: Budget | K29: Blocker | L29: Siehe Blatt „Werbung“. | M29: =IF(H29="erledigt","",IF(E29<TODAY(),"ÜBERFÄLLIG",IF(E29-TODAY()<=2,"bald fällig","")))
A30: 29 | B30: Werbung organisch | C30: Teaser-Ausschnitte festlegen (welche Videos/Lieder dürfen öffentlich?) | D30: 46320 | E30: 46322 | F30: =CHOOSE(WEEKDAY(E30,2),"Mo","Di","Mi","Do","Fr","Sa","So") -> Di | G30: Jannik | H30: offen | I30: hoch | J30: Rechteklärung bei geschützten Liedern | K30: Blocker | M30: =IF(H30="erledigt","",IF(E30<TODAY(),"ÜBERFÄLLIG",IF(E30-TODAY()<=2,"bald fällig","")))
A31: 30 | B31: Werbung bezahlt | C31: Werbebudget und Rahmen festlegen (Beispiel: 300–600 € ❓) | D31: 46320 | E31: 46322 | F31: =CHOOSE(WEEKDAY(E31,2),"Mo","Di","Mi","Do","Fr","Sa","So") -> Di | G31: Jannik + Eltern | H31: offen | I31: hoch | J31: Gesamtbudget | K31: Vorschlag ❓ (Claude) | L31: Bisher nicht eingeplant. Zahl ist nur ein Platzhalter. | M31: =IF(H31="erledigt","",IF(E31<TODAY(),"ÜBERFÄLLIG",IF(E31-TODAY()<=2,"bald fällig","")))
A32: 31 | B32: Recht & Rechte | C32: Teaser nur mit rechtefreien oder geklärten Liedern veröffentlichen | D32: 46320 | E32: 46322 | F32: =CHOOSE(WEEKDAY(E32,2),"Mo","Di","Mi","Do","Fr","Sa","So") -> Di | G32: Jannik | H32: offen | I32: hoch | K32: Vorschlag ❓ (Claude) | L32: Geschützte Titel: erst klären. | M32: =IF(H32="erledigt","",IF(E32<TODAY(),"ÜBERFÄLLIG",IF(E32-TODAY()<=2,"bald fällig","")))
A33: 32 | B33: Orga & Budget | C33: Kapazität prüfen: Schnittaufwand pro Video festlegen (Jannik 20 Std./Woche für Social Media, Shop, Warteliste, Schnitt) | D33: 46321 | E33: 46322 | F33: =CHOOSE(WEEKDAY(E33,2),"Mo","Di","Mi","Do","Fr","Sa","So") -> Di | G33: Jannik + Claude | H33: offen | I33: hoch | K33: Vorschlag ❓ (Claude) | L33: Risiko: 24 Videos, tägliche Posts und Shop-Aufbau in 3 Wochen. Videoagent für Rohschnitt nutzen, Vorlagen für Titel/Untertitel. | M33: =IF(H33="erledigt","",IF(E33<TODAY(),"ÜBERFÄLLIG",IF(E33-TODAY()<=2,"bald fällig","")))
A34: 33 | B34: Produktion | C34: 10 Geschichten-Themen mit David abstimmen und festlegen | D34: 46321 | E34: 46323 | F34: =CHOOSE(WEEKDAY(E34,2),"Mo","Di","Mi","Do","Fr","Sa","So") -> Mi | G34: Jannik + David | H34: offen | I34: hoch | J34: Themenvorschläge in [[Adventskalender-Drehplan]] | K34: Vorschlag ❓ (Claude) | M34: =IF(H34="erledigt","",IF(E34<TODAY(),"ÜBERFÄLLIG",IF(E34-TODAY()<=2,"bald fällig","")))
A35: 34 | B35: Produktion | C35: Dreh-Block A: Lieder (gleiche Kameraposition), 4 Videos | D35: 46323 | E35: 46323 | F35: =CHOOSE(WEEKDAY(E35,2),"Mo","Di","Mi","Do","Fr","Sa","So") -> Mi | G35: Mutter (Kamera) + David | H35: offen | I35: hoch | J35: Terminfreigabe David | K35: Vorschlag ❓ (Claude) | L35: Termin ❓ nur Vorschlag. | M35: =IF(H35="erledigt","",IF(E35<TODAY(),"ÜBERFÄLLIG",IF(E35-TODAY()<=2,"bald fällig","")))
A36: 35 | B36: Shop & Technik | C36: Shop-Hinweise: Start 1.12., täglich ein Türchen, späte Käufer sehen alles | D36: 46322 | E36: 46323 | F36: =CHOOSE(WEEKDAY(E36,2),"Mo","Di","Mi","Do","Fr","Sa","So") -> Mi | G36: Jannik + Claude | H36: offen | I36: hoch | K36: Beschluss Jannik | M36: =IF(H36="erledigt","",IF(E36<TODAY(),"ÜBERFÄLLIG",IF(E36-TODAY()<=2,"bald fällig","")))
A37: 36 | B37: Shop & Technik | C37: Bestellmail mit persönlichem Zugangslink einrichten | D37: 46322 | E37: 46323 | F37: =CHOOSE(WEEKDAY(E37,2),"Mo","Di","Mi","Do","Fr","Sa","So") -> Mi | G37: Jannik | H37: offen | I37: hoch | J37: Zugangssystem | K37: Beschluss Jannik | M37: =IF(H37="erledigt","",IF(E37<TODAY(),"ÜBERFÄLLIG",IF(E37-TODAY()<=2,"bald fällig","")))
A38: 37 | B38: Shop & Technik | C38: Landingpage Deutsch veröffentlichen (mit Warteliste und Kaufen-Button) | D38: 46321 | E38: 46323 | F38: =CHOOSE(WEEKDAY(E38,2),"Mo","Di","Mi","Do","Fr","Sa","So") -> Mi | G38: Jannik + Claude | H38: offen | I38: hoch | J38: Link/Text der Warteliste-Seite | K38: Beschluss Jannik | M38: =IF(H38="erledigt","",IF(E38<TODAY(),"ÜBERFÄLLIG",IF(E38-TODAY()<=2,"bald fällig","")))
A39: 38 | B39: Warteliste & Mail | C39: Brevo: Mails 1–3 einrichten (Bestätigung, Willkommen, Verkaufsstart) | D39: 46321 | E39: 46323 | F39: =CHOOSE(WEEKDAY(E39,2),"Mo","Di","Mi","Do","Fr","Sa","So") -> Mi | G39: Jannik | H39: offen | I39: hoch | J39: Absender, Texte | K39: Beschluss Jannik | M39: =IF(H39="erledigt","",IF(E39<TODAY(),"ÜBERFÄLLIG",IF(E39-TODAY()<=2,"bald fällig","")))
A40: 39 | B40: Werbung organisch | C40: Links in Bios setzen (Instagram, TikTok Business-Konto, Facebook, YouTube) auf Landingpage | D40: 46322 | E40: 46323 | F40: =CHOOSE(WEEKDAY(E40,2),"Mo","Di","Mi","Do","Fr","Sa","So") -> Mi | G40: Jannik | H40: offen | I40: hoch | J40: Landingpage | K40: Notion-Plan | L40: Nur der Bio-Link ist klickbar. | M40: =IF(H40="erledigt","",IF(E40<TODAY(),"ÜBERFÄLLIG",IF(E40-TODAY()<=2,"bald fällig","")))
...

Sheet Termine
A1: Datum | B1: Tag | C1: Termin | D1: Art | E1: Tage bis dahin
A2: 46321 | B2: =CHOOSE(WEEKDAY(A2,2),"Mo","Di","Mi","Do","Fr","Sa","So") -> Mo | C2: Mama erinnern (Mr. Lee), GEMA-Anfrage, Team und Budget festlegen | D2: Aufgabe | E2: =A2-TODAY() -> 2
A3: 46324 | B3: =CHOOSE(WEEKDAY(A3,2),"Mo","Di","Mi","Do","Fr","Sa","So") -> Do | C3: KAUFEN-BUTTON LIVE (spätester Termin), Testkauf | D3: Harte Frist | E3: =A3-TODAY() -> 5
A4: 46325 | B4: =CHOOSE(WEEKDAY(A4,2),"Mo","Di","Mi","Do","Fr","Sa","So") -> Fr | C4: Newsletter an die Altliste | D4: Aufgabe | E4: =A4-TODAY() -> 6
A5: 46341 | B5: =CHOOSE(WEEKDAY(A5,2),"Mo","Di","Mi","Do","Fr","Sa","So") -> So | C5: Alle 24 Videos fertig, letzter Tag Early Bird (25 €) | D5: Harte Frist | E5: =A5-TODAY() -> 22
A6: 46342 | B6: =CHOOSE(WEEKDAY(A6,2),"Mo","Di","Mi","Do","Fr","Sa","So") -> Mo | C6: Preis ab heute 29,99 € | D6: Preisänderung | E6: =A6-TODAY() -> 23
A7: 46355 | B7: =CHOOSE(WEEKDAY(A7,2),"Mo","Di","Mi","Do","Fr","Sa","So") -> So | C7: 1. Advent: YouTube-Musikvideo 1, Gewinnspiel 1 (12 oder 14 Uhr DE) | D7: Harte Frist | E7: =A7-TODAY() -> 36
A8: 46356 | B8: =CHOOSE(WEEKDAY(A8,2),"Mo","Di","Mi","Do","Fr","Sa","So") -> Mo | C8: Mail „Morgen Türchen 1“ | D8: Aufgabe | E8: =A8-TODAY() -> 37
A9: 46357 | B9: =CHOOSE(WEEKDAY(A9,2),"Mo","Di","Mi","Do","Fr","Sa","So") -> Di | C9: KALENDER STARTET: Türchen 1 | D9: Harte Frist | E9: =A9-TODAY() -> 38
A10: 46362 | B10: =CHOOSE(WEEKDAY(A10,2),"Mo","Di","Mi","Do","Fr","Sa","So") -> So | C10: 2. Advent: Live, Ziehung, Musikvideo-Türchen 6 | D10: Harte Frist | E10: =A10-TODAY() -> 43
A11: 46369 | B11: =CHOOSE(WEEKDAY(A11,2),"Mo","Di","Mi","Do","Fr","Sa","So") -> So | C11: 3. Advent: Live, Ziehung, Musikvideo-Türchen 13 | D11: Harte Frist | E11: =A11-TODAY() -> 50
A12: 46376 | B12: =CHOOSE(WEEKDAY(A12,2),"Mo","Di","Mi","Do","Fr","Sa","So") -> So | C12: 4. Advent: Live, Ziehung, 40 % CD-Rabatt, Musikvideo-Türchen 20 | D12: Harte Frist | E12: =A12-TODAY() -> 57
A13: 46380 | B13: =CHOOSE(WEEKDAY(A13,2),"Mo","Di","Mi","Do","Fr","Sa","So") -> Do | C13: Finale: Türchen 24, große Ziehung | D13: Harte Frist | E13: =A13-TODAY() -> 61

Sheet Werbung
A1: Phase | B1: Zeitraum | C1: Ziel | D1: Kanäle | E1: Inhalte / Ideen | F1: Messgröße (Beispiel ❓) | G1: Budget ❓
A2: 1 Teaser und Warteliste | B2: 24.10.–28.10. | C2: Warteliste füllen, Aufmerksamkeit | D2: Instagram, TikTok, Facebook, YouTube Community, Altliste, WhatsApp | E2: Teaser-Clips (30–45 Sek.), Behind the Scenes vom Dreh, „Trag dich ein“-Post, Bio-Links auf Landingpage | F2: Neue Wartelisten-Einträge | G2: 0 € (organisch)
A3: 2 Launch | B3: 29.10.–1.11. | C3: Erste Käufer, Early Bird | D3: Alle Kanäle, YouTube-Beschreibung und angepinnter Kommentar, Newsletter Altliste 30.10., Verkaufsstart-Mail | E3: Launch-Reel, Story mit Link, YouTube Community-Post, Erklärvideo „So funktioniert der Kalender“ | F3: Käufe, Klicks auf Landingpage | G3: Start Anzeigen ❓
A4: 3 Early-Bird-Druck | B4: 2.11.–15.11. | C4: Käufe vor dem 15.11. | D4: Meta-Anzeigen (Instagram/Facebook), YouTube-Anzeige ❓, organische Posts, Mails 11.11. und 15.11. | E4: Countdown (7 Tage, 3 Tage, letzter Tag), Social Proof (erste Reaktionen), Vorschau auf Türchen, Rabatt-Hinweis 25 € statt 29,99 € | F4: Käufe pro Tag, Kosten pro Kauf | G4: z. B. 150–300 € ❓
A5: 4 Nachlaunch + Korea/USA | B5: 16.11.–28.11. | C5: Weiter verkaufen, Korea und USA öffnen | D5: Meta-Anzeigen DE/KR/US ❓, Korea-Community über Mr. Lee, organische Posts | E5: „Noch 29,99 €, Start am 1.12.“, koreanische und englische Landingpage, Gewinnspiel-Vorschau, Behind the Scenes | F5: Käufe nach Land | G5: z. B. 150–300 € ❓
A6: 5 Countdown | B6: 25.11.–30.11. | C6: Spannung vor dem Start | D6: Stories, Reels, Mails, Premiere-Ankündigung 1. Advent | E6: „Noch X Tage“, Blick hinter Türchen 1, Gewinnspiel-Aufruf zum 1. Advent | F6: Aufrufe, Anmeldungen | G6: 0 € (organisch)
A7: 6 Kalenderphase | B7: 1.12.–24.12. | C7: Käufer halten, Nachkäufer gewinnen | D7: Tägliche Posts, Sonntags-Lives, Mails, Retargeting ❓ | E7: Täglicher Türchen-Teaser (ohne alles zu verraten), Wochen-Gewinnspiele, 20.12. CD-Rabatt, 24.12. Finale | F7: Käufe pro Woche, Teilnehmer an Gewinnspielen | G7: z. B. 100–200 € ❓
A8: 7 Nachbereitung | B8: 25.12.–31.12. | C8: Dank, Kunden binden, 2027 vorbereiten | D8: Mail, Instagram, YouTube | E8: Dank, Gewinner zeigen, Konzerte 2027 | F8: Neue Abonnenten, Newsletter-Öffnungen | G8: 0 €
A10: Hinweis: Alle Budgets, Messgrößen und bezahlten Kanäle sind Vorschläge von Claude (❓) und wurden von Jannik noch nicht entschieden. Quelle der organischen Idee „tägliche Clips“: Notion-Plan vom 6.10.2026.

Sheet Offene Fragen
A1: Nr | B1: Frage | C1: Wer antwortet | D1: Wird gebraucht bis | E1: Status | F1: Antwort (Jannik, 24.10.)
A2: 1 | B2: Wer macht was im Team, wie viele Stunden pro Woche? | C2: Jannik + Eltern | D2: 46321 | E2: beantwortet | F2: Jannik 20 Std./Woche: Social Media, Warteliste, Website/Shop, Konzerte, Videoschnitt. Mutter: Videodreh. Vater: vor der Kamera. Eltern zusammen ca. 10 Std./Woche.
A3: 2 | B3: Gesamtbudget und Werbebudget? | C3: Jannik + Eltern | D3: 46322 | E3: offen | F3: Jannik fragt nach.
A4: 3 | B4: Welche Lieder (alle) sind im Kalender, welches Playback ist eigen oder fremd? | C4: Jannik + David | D4: 46322 | E4: offen | F4: Jannik fragt nach (Playback eigen oder fremd).
A5: 4 | B5: Dreh-Termine von David (Blöcke A–E)? | C5: Jannik + David | D5: 46321 | E5: offen | F5: Noch keine Termine.
A6: 5 | B6: Zugang: Plugin oder eigener Server, wer baut es, Admin-Zugang? | C6: Jannik | D6: 46321 | E6: offen
A7: 6 | B7: Zahlarten außer PayPal, Verkauf weltweit? | C7: Jannik | D7: 46322 | E7: beantwortet | F7: PayPal und alles, was der Shop liefert.
A8: 7 | B8: Link oder Text der aktuellen Warteliste-Seite? | C8: Jannik | D8: 46320 | E8: offen | F8: Jannik fragt an und schickt es.
A9: 8 | B9: Text der Konzertseite 2027 (Homepage)? | C9: Jannik | D9: 46320 | E9: offen | F9: Auf der Homepage. Claude hat in dieser Sitzung keinen Browser, Jannik kopiert den Text.
A10: 9 | B10: Absender-Name und -Adresse in Brevo? | C10: Jannik | D10: 46321 | E10: offen | F10: Jannik nennt ihn später.
A11: 10 | B11: Welche Teaser-Ausschnitte dürfen öffentlich werden? | C11: Jannik | D11: 46322 | E11: offen | F11: Jannik sagt später, welche.
A12: 11 | B12: Welche Videos bekommen eine englische und koreanische Fassung? | C12: Jannik | D12: 46323 | E12: beantwortet | F12: Alle, die keine Musik sind (Geschichten u. ä.).
A13: 12 | B13: Wann bis wann zählt ein Kauf für die jeweilige Ziehung (z. B. bis Ziehungstag 12 Uhr)? | C13: Jannik | D13: 46327 | E13: beantwortet | F13: Kauf zählt ab Verkaufsstart bis zum Beginn der jeweiligen Ziehung (Claude-Auslegung, bitte bestätigen).
A14: 13 | B14: Live-Plattform (YouTube/TikTok) und Uhrzeit (12 oder 14 Uhr DE)? | C14: Jannik + David | D14: 46334 | E14: beantwortet | F14: YouTube, 14 Uhr deutsche Zeit.
A15: 14 | B15: Mindestalter und Länderliste für das Gewinnspiel? | C15: Jannik + Kanzlei | D15: 46327 | E15: beantwortet | F15: 18. Länder: Deutschland, Niederlande, Tschechien, Frankreich, Schweiz, Österreich, Luxemburg, Belgien, Südkorea, USA, Paraguay.
A16: 15 | B16: Türchen 24: Breite und Höhe dreifach oder Fläche dreifach? | C16: Jannik | D16: 46327 | E16: beantwortet | F16: Breite dreifach, Höhe gleich wie die anderen Türchen (Jannik, 24.10.).
A17: 16 | B17: Videoformat des Kalenders: 16:9? | C17: Jannik | D17: 46321 | E17: beantwortet | F17: 16:9.
A18: 17 | B18: Welche Werbekanäle bezahlt (Meta, YouTube) und welches Budget? | C18: Jannik + Eltern | D18: 46322 | E18: offen | F18: Kanäle und Budget müssen noch festgelegt werden.
A19: 18 | B19: Wer schneidet die Videos (Jannik, Videoagent, extern)? | C19: Jannik | D19: 46321 | E19: beantwortet | F19: Jannik und Videoagent.
